2020-03-30 20:38:19,233 ERROR: Exception on /login [GET] [in d:\python\lib\site-packages\flask\app.py:1891]
Traceback (most recent call last):
  File "d:\python\lib\site-packages\flask\app.py", line 2446, in wsgi_app
    response = self.full_dispatch_request()
  File "d:\python\lib\site-packages\flask\app.py", line 1951, in full_dispatch_request
    rv = self.handle_user_exception(e)
  File "d:\python\lib\site-packages\flask\app.py", line 1820, in handle_user_exception
    reraise(exc_type, exc_value, tb)
  File "d:\python\lib\site-packages\flask\_compat.py", line 39, in reraise
    raise value
  File "d:\python\lib\site-packages\flask\app.py", line 1949, in full_dispatch_request
    rv = self.dispatch_request()
  File "d:\python\lib\site-packages\flask\app.py", line 1935, in dispatch_request
    return self.view_functions[rule.endpoint](**req.view_args)
  File "E:\Ç®À¤\Á·Ï°\python\testProject_032620\app\routes.py", line 67, in login
    return render_template('login.html',title='Sign In', form=form)
  File "d:\python\lib\site-packages\flask\templating.py", line 138, in render_template
    ctx.app.jinja_env.get_or_select_template(template_name_or_list),
  File "d:\python\lib\site-packages\jinja2\environment.py", line 930, in get_or_select_template
    return self.get_template(template_name_or_list, parent, globals)
  File "d:\python\lib\site-packages\jinja2\environment.py", line 883, in get_template
    return self._load_template(name, self.make_globals(globals))
  File "d:\python\lib\site-packages\jinja2\environment.py", line 857, in _load_template
    template = self.loader.load(self, name, globals)
  File "d:\python\lib\site-packages\jinja2\loaders.py", line 129, in load
    code = environment.compile(source, name, filename)
  File "d:\python\lib\site-packages\jinja2\environment.py", line 638, in compile
    self.handle_exception(source=source_hint)
  File "d:\python\lib\site-packages\jinja2\environment.py", line 832, in handle_exception
    reraise(*rewrite_traceback_stack(source=source))
  File "d:\python\lib\site-packages\jinja2\_compat.py", line 28, in reraise
    raise value.with_traceback(tb)
  File "E:\Ç®À¤\Á·Ï°\python\testProject_032620\app\templates\login.html", line 20, in template
    <!--{% block app_content %}-->
jinja2.exceptions.TemplateAssertionError: block 'app_content' defined twice
2020-03-30 20:40:07,581 INFO: Microblog startup [in E:\Ç®À¤\Á·Ï°\python\testProject_032620\app\__init__.py:57]
