2020-03-29 21:21:27,341 ERROR: Exception on /index [GET] [in d:\python\lib\site-packages\flask\app.py:1891]
Traceback (most recent call last):
  File "d:\python\lib\site-packages\flask\app.py", line 2446, in wsgi_app
    response = self.full_dispatch_request()
  File "d:\python\lib\site-packages\flask\app.py", line 1951, in full_dispatch_request
    rv = self.handle_user_exception(e)
  File "d:\python\lib\site-packages\flask\app.py", line 1820, in handle_user_exception
    reraise(exc_type, exc_value, tb)
  File "d:\python\lib\site-packages\flask\_compat.py", line 39, in reraise
    raise value
  File "d:\python\lib\site-packages\flask\app.py", line 1949, in full_dispatch_request
    rv = self.dispatch_request()
  File "d:\python\lib\site-packages\flask\app.py", line 1935, in dispatch_request
    return self.view_functions[rule.endpoint](**req.view_args)
  File "d:\python\lib\site-packages\flask_login\utils.py", line 272, in decorated_view
    return func(*args, **kwargs)
  File "E:\Ç®À¤\Á·Ï°\python\testProject_032620\app\routes.py", line 19, in index
    form = PostForm()
  File "d:\python\lib\site-packages\wtforms\form.py", line 212, in __call__
    return type.__call__(cls, *args, **kwargs)
  File "d:\python\lib\site-packages\flask_wtf\form.py", line 87, in __init__
    super(FlaskForm, self).__init__(formdata=formdata, **kwargs)
  File "d:\python\lib\site-packages\wtforms\form.py", line 272, in __init__
    super(Form, self).__init__(self._unbound_fields, meta=meta_obj, prefix=prefix)
  File "d:\python\lib\site-packages\wtforms\form.py", line 52, in __init__
    field = meta.bind_field(self, unbound_field, options)
  File "d:\python\lib\site-packages\wtforms\meta.py", line 27, in bind_field
    return unbound_field.bind(form=form, **options)
  File "d:\python\lib\site-packages\wtforms\fields\core.py", line 353, in bind
    return self.field_class(*self.args, **kw)
TypeError: __init__() got an unexpected keyword argument 'vallidators'
2020-03-29 21:21:33,809 ERROR: Exception on /index [GET] [in d:\python\lib\site-packages\flask\app.py:1891]
Traceback (most recent call last):
  File "d:\python\lib\site-packages\flask\app.py", line 2446, in wsgi_app
    response = self.full_dispatch_request()
  File "d:\python\lib\site-packages\flask\app.py", line 1951, in full_dispatch_request
    rv = self.handle_user_exception(e)
  File "d:\python\lib\site-packages\flask\app.py", line 1820, in handle_user_exception
    reraise(exc_type, exc_value, tb)
  File "d:\python\lib\site-packages\flask\_compat.py", line 39, in reraise
    raise value
  File "d:\python\lib\site-packages\flask\app.py", line 1949, in full_dispatch_request
    rv = self.dispatch_request()
  File "d:\python\lib\site-packages\flask\app.py", line 1935, in dispatch_request
    return self.view_functions[rule.endpoint](**req.view_args)
  File "d:\python\lib\site-packages\flask_login\utils.py", line 272, in decorated_view
    return func(*args, **kwargs)
  File "E:\Ç®À¤\Á·Ï°\python\testProject_032620\app\routes.py", line 19, in index
    form = PostForm()
  File "d:\python\lib\site-packages\wtforms\form.py", line 212, in __call__
    return type.__call__(cls, *args, **kwargs)
  File "d:\python\lib\site-packages\flask_wtf\form.py", line 87, in __init__
    super(FlaskForm, self).__init__(formdata=formdata, **kwargs)
  File "d:\python\lib\site-packages\wtforms\form.py", line 272, in __init__
    super(Form, self).__init__(self._unbound_fields, meta=meta_obj, prefix=prefix)
  File "d:\python\lib\site-packages\wtforms\form.py", line 52, in __init__
    field = meta.bind_field(self, unbound_field, options)
  File "d:\python\lib\site-packages\wtforms\meta.py", line 27, in bind_field
    return unbound_field.bind(form=form, **options)
  File "d:\python\lib\site-packages\wtforms\fields\core.py", line 353, in bind
    return self.field_class(*self.args, **kw)
TypeError: __init__() got an unexpected keyword argument 'vallidators'
2020-03-29 21:21:36,180 ERROR: Exception on /index [GET] [in d:\python\lib\site-packages\flask\app.py:1891]
Traceback (most recent call last):
  File "d:\python\lib\site-packages\flask\app.py", line 2446, in wsgi_app
    response = self.full_dispatch_request()
  File "d:\python\lib\site-packages\flask\app.py", line 1951, in full_dispatch_request
    rv = self.handle_user_exception(e)
  File "d:\python\lib\site-packages\flask\app.py", line 1820, in handle_user_exception
    reraise(exc_type, exc_value, tb)
  File "d:\python\lib\site-packages\flask\_compat.py", line 39, in reraise
    raise value
  File "d:\python\lib\site-packages\flask\app.py", line 1949, in full_dispatch_request
    rv = self.dispatch_request()
  File "d:\python\lib\site-packages\flask\app.py", line 1935, in dispatch_request
    return self.view_functions[rule.endpoint](**req.view_args)
  File "d:\python\lib\site-packages\flask_login\utils.py", line 272, in decorated_view
    return func(*args, **kwargs)
  File "E:\Ç®À¤\Á·Ï°\python\testProject_032620\app\routes.py", line 19, in index
    form = PostForm()
  File "d:\python\lib\site-packages\wtforms\form.py", line 212, in __call__
    return type.__call__(cls, *args, **kwargs)
  File "d:\python\lib\site-packages\flask_wtf\form.py", line 87, in __init__
    super(FlaskForm, self).__init__(formdata=formdata, **kwargs)
  File "d:\python\lib\site-packages\wtforms\form.py", line 272, in __init__
    super(Form, self).__init__(self._unbound_fields, meta=meta_obj, prefix=prefix)
  File "d:\python\lib\site-packages\wtforms\form.py", line 52, in __init__
    field = meta.bind_field(self, unbound_field, options)
  File "d:\python\lib\site-packages\wtforms\meta.py", line 27, in bind_field
    return unbound_field.bind(form=form, **options)
  File "d:\python\lib\site-packages\wtforms\fields\core.py", line 353, in bind
    return self.field_class(*self.args, **kw)
TypeError: __init__() got an unexpected keyword argument 'vallidators'
2020-03-29 21:22:29,983 ERROR: Exception on /index [GET] [in d:\python\lib\site-packages\flask\app.py:1891]
Traceback (most recent call last):
  File "d:\python\lib\site-packages\flask\app.py", line 2446, in wsgi_app
    response = self.full_dispatch_request()
  File "d:\python\lib\site-packages\flask\app.py", line 1951, in full_dispatch_request
    rv = self.handle_user_exception(e)
  File "d:\python\lib\site-packages\flask\app.py", line 1820, in handle_user_exception
    reraise(exc_type, exc_value, tb)
  File "d:\python\lib\site-packages\flask\_compat.py", line 39, in reraise
    raise value
  File "d:\python\lib\site-packages\flask\app.py", line 1949, in full_dispatch_request
    rv = self.dispatch_request()
  File "d:\python\lib\site-packages\flask\app.py", line 1935, in dispatch_request
    return self.view_functions[rule.endpoint](**req.view_args)
  File "d:\python\lib\site-packages\flask_login\utils.py", line 272, in decorated_view
    return func(*args, **kwargs)
  File "E:\Ç®À¤\Á·Ï°\python\testProject_032620\app\routes.py", line 19, in index
    form = PostForm()
  File "d:\python\lib\site-packages\wtforms\form.py", line 212, in __call__
    return type.__call__(cls, *args, **kwargs)
  File "d:\python\lib\site-packages\flask_wtf\form.py", line 87, in __init__
    super(FlaskForm, self).__init__(formdata=formdata, **kwargs)
  File "d:\python\lib\site-packages\wtforms\form.py", line 272, in __init__
    super(Form, self).__init__(self._unbound_fields, meta=meta_obj, prefix=prefix)
  File "d:\python\lib\site-packages\wtforms\form.py", line 52, in __init__
    field = meta.bind_field(self, unbound_field, options)
  File "d:\python\lib\site-packages\wtforms\meta.py", line 27, in bind_field
    return unbound_field.bind(form=form, **options)
  File "d:\python\lib\site-packages\wtforms\fields\core.py", line 353, in bind
    return self.field_class(*self.args, **kw)
TypeError: __init__() got an unexpected keyword argument 'vallidators'
2020-03-29 21:22:43,064 ERROR: Exception on / [GET] [in d:\python\lib\site-packages\flask\app.py:1891]
Traceback (most recent call last):
  File "d:\python\lib\site-packages\flask\app.py", line 2446, in wsgi_app
    response = self.full_dispatch_request()
  File "d:\python\lib\site-packages\flask\app.py", line 1951, in full_dispatch_request
    rv = self.handle_user_exception(e)
  File "d:\python\lib\site-packages\flask\app.py", line 1820, in handle_user_exception
    reraise(exc_type, exc_value, tb)
  File "d:\python\lib\site-packages\flask\_compat.py", line 39, in reraise
    raise value
  File "d:\python\lib\site-packages\flask\app.py", line 1949, in full_dispatch_request
    rv = self.dispatch_request()
  File "d:\python\lib\site-packages\flask\app.py", line 1935, in dispatch_request
    return self.view_functions[rule.endpoint](**req.view_args)
  File "d:\python\lib\site-packages\flask_login\utils.py", line 272, in decorated_view
    return func(*args, **kwargs)
  File "E:\Ç®À¤\Á·Ï°\python\testProject_032620\app\routes.py", line 19, in index
    form = PostForm()
  File "d:\python\lib\site-packages\wtforms\form.py", line 212, in __call__
    return type.__call__(cls, *args, **kwargs)
  File "d:\python\lib\site-packages\flask_wtf\form.py", line 87, in __init__
    super(FlaskForm, self).__init__(formdata=formdata, **kwargs)
  File "d:\python\lib\site-packages\wtforms\form.py", line 272, in __init__
    super(Form, self).__init__(self._unbound_fields, meta=meta_obj, prefix=prefix)
  File "d:\python\lib\site-packages\wtforms\form.py", line 52, in __init__
    field = meta.bind_field(self, unbound_field, options)
  File "d:\python\lib\site-packages\wtforms\meta.py", line 27, in bind_field
    return unbound_field.bind(form=form, **options)
  File "d:\python\lib\site-packages\wtforms\fields\core.py", line 353, in bind
    return self.field_class(*self.args, **kw)
TypeError: __init__() got an unexpected keyword argument 'vallidators'
