2020-04-03 10:55:50,353 ERROR: Exception on / [GET] [in d:\python\lib\site-packages\flask\app.py:1891]
Traceback (most recent call last):
  File "d:\python\lib\site-packages\flask\app.py", line 2446, in wsgi_app
    response = self.full_dispatch_request()
  File "d:\python\lib\site-packages\flask\app.py", line 1951, in full_dispatch_request
    rv = self.handle_user_exception(e)
  File "d:\python\lib\site-packages\flask\app.py", line 1820, in handle_user_exception
    reraise(exc_type, exc_value, tb)
  File "d:\python\lib\site-packages\flask\_compat.py", line 39, in reraise
    raise value
  File "d:\python\lib\site-packages\flask\app.py", line 1949, in full_dispatch_request
    rv = self.dispatch_request()
  File "d:\python\lib\site-packages\flask\app.py", line 1935, in dispatch_request
    return self.view_functions[rule.endpoint](**req.view_args)
  File "d:\python\lib\site-packages\flask_login\utils.py", line 272, in decorated_view
    return func(*args, **kwargs)
  File "E:\Ç®À¤\Á·Ï°\python\testProject_032620\app\main\routes.py", line 51, in index
    next_url=next_url, prev_url=prev_url)
  File "d:\python\lib\site-packages\flask\templating.py", line 140, in render_template
    ctx.app,
  File "d:\python\lib\site-packages\flask\templating.py", line 120, in _render
    rv = template.render(context)
  File "d:\python\lib\site-packages\jinja2\environment.py", line 1090, in render
    self.environment.handle_exception()
  File "d:\python\lib\site-packages\jinja2\environment.py", line 832, in handle_exception
    reraise(*rewrite_traceback_stack(source=source))
  File "d:\python\lib\site-packages\jinja2\_compat.py", line 28, in reraise
    raise value.with_traceback(tb)
  File "E:\Ç®À¤\Á·Ï°\python\testProject_032620\app\templates\index.html", line 2, in top-level template code
    {% import 'bootstrap/wtf.html' as wtf %}
  File "E:\Ç®À¤\Á·Ï°\python\testProject_032620\app\templates\base.html", line 1, in top-level template code
    {% extends 'bootstrap/base.html' %}
  File "d:\python\lib\site-packages\flask_bootstrap\templates\bootstrap\base.html", line 1, in top-level template code
    {% block doc -%}
  File "d:\python\lib\site-packages\flask_bootstrap\templates\bootstrap\base.html", line 3, in block "doc"
    <html{% block html_attribs %}{% endblock html_attribs %}>
  File "d:\python\lib\site-packages\flask_bootstrap\templates\bootstrap\base.html", line 11, in block "html"
    {%- endblock metas %}
  File "d:\python\lib\site-packages\flask_bootstrap\templates\bootstrap\base.html", line 12, in block "body"
  File "E:\Ç®À¤\Á·Ï°\python\testProject_032620\app\templates\base.html", line 29, in block "navbar"
    <li><a href="{{ url_for('main.logout') }}">{{ _('Logout') }}</a></li>
  File "d:\python\lib\site-packages\flask\helpers.py", line 370, in url_for
    return appctx.app.handle_url_build_error(error, endpoint, values)
  File "d:\python\lib\site-packages\flask\app.py", line 2215, in handle_url_build_error
    reraise(exc_type, exc_value, tb)
  File "d:\python\lib\site-packages\flask\_compat.py", line 39, in reraise
    raise value
  File "d:\python\lib\site-packages\flask\helpers.py", line 358, in url_for
    endpoint, values, method=method, force_external=external
  File "d:\python\lib\site-packages\werkzeug\routing.py", line 2179, in build
    raise BuildError(endpoint, values, method, self)
werkzeug.routing.BuildError: Could not build url for endpoint 'main.logout'. Did you mean 'auth.logout' instead?
2020-04-03 10:57:16,119 INFO: Microblog startup [in E:\Ç®À¤\Á·Ï°\python\testProject_032620\app\__init__.py:84]
2020-04-03 10:57:54,724 ERROR: Exception on /user/aa [GET] [in d:\python\lib\site-packages\flask\app.py:1891]
Traceback (most recent call last):
  File "d:\python\lib\site-packages\flask\app.py", line 2446, in wsgi_app
    response = self.full_dispatch_request()
  File "d:\python\lib\site-packages\flask\app.py", line 1951, in full_dispatch_request
    rv = self.handle_user_exception(e)
  File "d:\python\lib\site-packages\flask\app.py", line 1820, in handle_user_exception
    reraise(exc_type, exc_value, tb)
  File "d:\python\lib\site-packages\flask\_compat.py", line 39, in reraise
    raise value
  File "d:\python\lib\site-packages\flask\app.py", line 1949, in full_dispatch_request
    rv = self.dispatch_request()
  File "d:\python\lib\site-packages\flask\app.py", line 1935, in dispatch_request
    return self.view_functions[rule.endpoint](**req.view_args)
  File "d:\python\lib\site-packages\flask_login\utils.py", line 272, in decorated_view
    return func(*args, **kwargs)
  File "E:\Ç®À¤\Á·Ï°\python\testProject_032620\app\main\routes.py", line 77, in user
    if posts.has_next else None
  File "d:\python\lib\site-packages\flask\helpers.py", line 370, in url_for
    return appctx.app.handle_url_build_error(error, endpoint, values)
  File "d:\python\lib\site-packages\flask\app.py", line 2215, in handle_url_build_error
    reraise(exc_type, exc_value, tb)
  File "d:\python\lib\site-packages\flask\_compat.py", line 39, in reraise
    raise value
  File "d:\python\lib\site-packages\flask\helpers.py", line 358, in url_for
    endpoint, values, method=method, force_external=external
  File "d:\python\lib\site-packages\werkzeug\routing.py", line 2179, in build
    raise BuildError(endpoint, values, method, self)
werkzeug.routing.BuildError: Could not build url for endpoint 'user' with values ['page', 'username']. Did you mean 'main.user' instead?
2020-04-03 11:00:13,345 INFO: Microblog startup [in E:\Ç®À¤\Á·Ï°\python\testProject_032620\app\__init__.py:84]
2020-04-03 11:00:30,330 ERROR: Exception on /edit_profile [POST] [in d:\python\lib\site-packages\flask\app.py:1891]
Traceback (most recent call last):
  File "d:\python\lib\site-packages\flask\app.py", line 2446, in wsgi_app
    response = self.full_dispatch_request()
  File "d:\python\lib\site-packages\flask\app.py", line 1951, in full_dispatch_request
    rv = self.handle_user_exception(e)
  File "d:\python\lib\site-packages\flask\app.py", line 1820, in handle_user_exception
    reraise(exc_type, exc_value, tb)
  File "d:\python\lib\site-packages\flask\_compat.py", line 39, in reraise
    raise value
  File "d:\python\lib\site-packages\flask\app.py", line 1949, in full_dispatch_request
    rv = self.dispatch_request()
  File "d:\python\lib\site-packages\flask\app.py", line 1935, in dispatch_request
    return self.view_functions[rule.endpoint](**req.view_args)
  File "d:\python\lib\site-packages\flask_login\utils.py", line 272, in decorated_view
    return func(*args, **kwargs)
  File "E:\Ç®À¤\Á·Ï°\python\testProject_032620\app\main\routes.py", line 93, in edit_profile
    return redirect(url_for('edit_profile'))
  File "d:\python\lib\site-packages\flask\helpers.py", line 370, in url_for
    return appctx.app.handle_url_build_error(error, endpoint, values)
  File "d:\python\lib\site-packages\flask\app.py", line 2215, in handle_url_build_error
    reraise(exc_type, exc_value, tb)
  File "d:\python\lib\site-packages\flask\_compat.py", line 39, in reraise
    raise value
  File "d:\python\lib\site-packages\flask\helpers.py", line 358, in url_for
    endpoint, values, method=method, force_external=external
  File "d:\python\lib\site-packages\werkzeug\routing.py", line 2179, in build
    raise BuildError(endpoint, values, method, self)
werkzeug.routing.BuildError: Could not build url for endpoint 'edit_profile'. Did you mean 'main.edit_profile' instead?
2020-04-03 11:01:22,520 INFO: Microblog startup [in E:\Ç®À¤\Á·Ï°\python\testProject_032620\app\__init__.py:84]
2020-04-04 17:06:49,275 INFO: Microblog startup [in E:\Ç®À¤\Á·Ï°\python\testProject_032620\app\__init__.py:89]
2020-04-04 17:07:12,971 ERROR: Exception on /search [GET] [in d:\python\lib\site-packages\flask\app.py:1891]
Traceback (most recent call last):
  File "d:\python\lib\site-packages\flask\app.py", line 2446, in wsgi_app
    response = self.full_dispatch_request()
  File "d:\python\lib\site-packages\flask\app.py", line 1951, in full_dispatch_request
    rv = self.handle_user_exception(e)
  File "d:\python\lib\site-packages\flask\app.py", line 1820, in handle_user_exception
    reraise(exc_type, exc_value, tb)
  File "d:\python\lib\site-packages\flask\_compat.py", line 39, in reraise
    raise value
  File "d:\python\lib\site-packages\flask\app.py", line 1949, in full_dispatch_request
    rv = self.dispatch_request()
  File "d:\python\lib\site-packages\flask\app.py", line 1935, in dispatch_request
    return self.view_functions[rule.endpoint](**req.view_args)
  File "d:\python\lib\site-packages\flask_login\utils.py", line 272, in decorated_view
    return func(*args, **kwargs)
  File "E:\Ç®À¤\Á·Ï°\python\testProject_032620\app\main\routes.py", line 148, in search
    current_app.config['POSTS_PER_PAGE'])
  File "E:\Ç®À¤\Á·Ï°\python\testProject_032620\app\models.py", line 18, in search
    ids, total = query_index(cls.__tablename__, expression, page, per_page)
  File "E:\Ç®À¤\Á·Ï°\python\testProject_032620\app\search.py", line 24, in query_index
    'from': (page - 1) * per_page, 'size': per_page})
  File "d:\python\lib\site-packages\elasticsearch\client\utils.py", line 92, in _wrapped
    return func(*args, params=params, headers=headers, **kwargs)
  File "d:\python\lib\site-packages\elasticsearch\client\__init__.py", line 1627, in search
    body=body,
  File "d:\python\lib\site-packages\elasticsearch\transport.py", line 362, in perform_request
    timeout=timeout,
  File "d:\python\lib\site-packages\elasticsearch\connection\http_urllib3.py", line 248, in perform_request
    self._raise_error(response.status, raw_data)
  File "d:\python\lib\site-packages\elasticsearch\connection\base.py", line 244, in _raise_error
    status_code, error_message, additional_info
elasticsearch.exceptions.NotFoundError: NotFoundError(404, 'index_not_found_exception', 'no such index [post]', post, index_or_alias)
2020-04-04 17:10:47,932 INFO: Microblog startup [in E:\Ç®À¤\Á·Ï°\python\testProject_032620\app\__init__.py:89]
